/home/atp2023/uji_coba/radar/main.py:41: UserWarning: frames=None which we can infer the length of, did not pass an explicit *save_count* and passed cache_frame_data=True.  To avoid a possibly unbounded cache, frame data caching has been disabled. To suppress this warning either pass `cache_frame_data=False` or `save_count=MAX_FRAMES`.
  self.ani = animation.FuncAnimation(self.fig, self.update_plot, interval=1000, blit=True)
Exception in Tkinter callback
Traceback (most recent call last):
  File "/usr/local/lib/python3.8/dist-packages/matplotlib/axis.py", line 1770, in convert_units
    ret = self.converter.convert(x, self.units, self)
  File "/usr/local/lib/python3.8/dist-packages/matplotlib/category.py", line 49, in convert
    raise ValueError(
ValueError: Missing category information for StrCategoryConverter; this might be caused by unintendedly mixing categorical and numeric data

The above exception was the direct cause of the following exception:

Traceback (most recent call last):
  File "/usr/lib/python3.8/tkinter/__init__.py", line 1883, in __call__
    return self.func(*args)
  File "/usr/lib/python3.8/tkinter/__init__.py", line 804, in callit
    func(*args)
  File "/usr/local/lib/python3.8/dist-packages/matplotlib/backends/_backend_tk.py", line 142, in _on_timer
    super()._on_timer()
  File "/usr/local/lib/python3.8/dist-packages/matplotlib/backend_bases.py", line 1226, in _on_timer
    ret = func(*args, **kwargs)
  File "/usr/local/lib/python3.8/dist-packages/matplotlib/animation.py", line 1426, in _step
    still_going = super()._step(*args)
  File "/usr/local/lib/python3.8/dist-packages/matplotlib/animation.py", line 1119, in _step
    self._draw_next_frame(framedata, self._blit)
  File "/usr/local/lib/python3.8/dist-packages/matplotlib/animation.py", line 1138, in _draw_next_frame
    self._draw_frame(framedata)
  File "/usr/local/lib/python3.8/dist-packages/matplotlib/animation.py", line 1767, in _draw_frame
    self._drawn_artists = self._func(framedata, *self._args)
  File "/home/atp2023/uji_coba/radar/main.py", line 80, in update_plot
    self.ax.relim()
  File "/usr/local/lib/python3.8/dist-packages/matplotlib/axes/_base.py", line 2479, in relim
    self._update_line_limits(artist)
  File "/usr/local/lib/python3.8/dist-packages/matplotlib/axes/_base.py", line 2327, in _update_line_limits
    path = line.get_path()
  File "/usr/local/lib/python3.8/dist-packages/matplotlib/lines.py", line 1028, in get_path
    self.recache()
  File "/usr/local/lib/python3.8/dist-packages/matplotlib/lines.py", line 658, in recache
    xconv = self.convert_xunits(self._xorig)
  File "/usr/local/lib/python3.8/dist-packages/matplotlib/artist.py", line 281, in convert_xunits
    return ax.xaxis.convert_units(x)
  File "/usr/local/lib/python3.8/dist-packages/matplotlib/axis.py", line 1772, in convert_units
    raise munits.ConversionError('Failed to convert value(s) to axis '
matplotlib.units.ConversionError: Failed to convert value(s) to axis units: ['21:12:30']
